<?xml version="1.0" ?>
<!-- =================================================================================== -->
<!-- |    This document was autogenerated by xacro from /home/jk/workspace/src/kabot_description/models/diff_drive/kabot.urdf.xacro | -->
<!-- |    EDITING THIS FILE BY HAND IS NOT RECOMMENDED                                 | -->
<!-- =================================================================================== -->
<robot name="kabot">
  <!-- Specify some standard inertial calculations https://en.wikipedia.org/wiki/List_of_moments_of_inertia -->
  <!-- These make use of xacro's mathematical functionality -->
  <material name="white">
    <color rgba="1.0 1.0 1.0 1.0"/>
  </material>
  <material name="red">
    <color rgba="1.0 0.0 0.0 1.0"/>
  </material>
  <material name="green">
    <color rgba="0.0 1.0 0.0 1.0"/>
  </material>
  <material name="blue">
    <color rgba="0.0 0.0 1.0 1.0"/>
  </material>
  <material name="black">
    <color rgba="0.0 0.0 1.0 1.0"/>
  </material>
  <link name="base_link"/>
  <link name="footprint_link"/>
  <link name="chassis_link">
    <visual>
      <geometry>
        <cylinder length="0.07" radius="0.06"/>
      </geometry>
      <material name="white"/>
    </visual>
    <collision>
      <geometry>
        <cylinder length="0.07" radius="0.06"/>
      </geometry>
    </collision>
    <inertial>
      <origin rpy="0 0 0" xyz="0 0 0"/>
      <mass value="0.1"/>
      <inertia ixx="0.00013083333333333333" ixy="0.0" ixz="0.0" iyy="0.00013083333333333333" iyz="0.0" izz="0.00018"/>
    </inertial>
  </link>
  <joint name="footprint_joint" type="fixed">
    <parent link="base_link"/>
    <child link="footprint_link"/>
    <origin xyz="0.0 0.0 -0.035"/>
  </joint>
  <joint name="chassis_joint" type="fixed">
    <parent link="base_link"/>
    <child link="chassis_link"/>
    <origin xyz="0.0 0.0 0.0"/>
  </joint>
  <gazebo reference="chassis_link">
    <material>Gazebo/Orange</material>
  </gazebo>
  <!-- Specify some standard inertial calculations https://en.wikipedia.org/wiki/List_of_moments_of_inertia -->
  <!-- These make use of xacro's mathematical functionality -->
  <link name="left_wheel_link">
    <visual>
      <geometry>
        <cylinder length="0.005" radius="0.035"/>
      </geometry>
      <material name="blue"/>
    </visual>
    <collision>
      <geometry>
        <cylinder length="0.005" radius="0.035"/>
      </geometry>
    </collision>
    <inertial>
      <origin rpy="0 0 0" xyz="0 0 0"/>
      <mass value="0.1"/>
      <inertia ixx="3.0833333333333335e-05" ixy="0.0" ixz="0.0" iyy="3.0833333333333335e-05" iyz="0.0" izz="6.125000000000001e-05"/>
    </inertial>
  </link>
  <joint name="left_wheel_joint" type="continuous">
    <parent link="chassis_link"/>
    <child link="left_wheel_link"/>
    <origin rpy="-1.5707963267948966 0 0" xyz="0 0.065 -0.005"/>
    <axis xyz="0 0 1"/>
  </joint>
  <gazebo reference="left_wheel_link">
    <material>Gazebo/Blue</material>
  </gazebo>
  <link name="right_wheel_link">
    <visual>
      <geometry>
        <cylinder length="0.005" radius="0.035"/>
      </geometry>
      <material name="blue"/>
    </visual>
    <collision>
      <geometry>
        <cylinder length="0.005" radius="0.035"/>
      </geometry>
    </collision>
    <inertial>
      <origin rpy="0 0 0" xyz="0 0 0"/>
      <mass value="0.1"/>
      <inertia ixx="3.0833333333333335e-05" ixy="0.0" ixz="0.0" iyy="3.0833333333333335e-05" iyz="0.0" izz="6.125000000000001e-05"/>
    </inertial>
  </link>
  <joint name="right_wheel_joint" type="continuous">
    <parent link="chassis_link"/>
    <child link="right_wheel_link"/>
    <origin rpy="-1.5707963267948966 0 0" xyz="0 -0.065 -0.005"/>
    <axis xyz="0 0 1"/>
  </joint>
  <gazebo reference="right_wheel_link">
    <material>Gazebo/Blue</material>
  </gazebo>
  <!-- DIFF DRIVE SIMULATION -->
  <gazebo>
    <plugin filename="ignition-gazebo-diff-drive-system" name="ignition::gazebo::systems::DiffDrive">
      <left_joint>left_wheel_joint</left_joint>
      <right_joint>right_wheel_joint</right_joint>
      <wheel_separation>0.13</wheel_separation>
      <wheel_radius>0.35</wheel_radius>
      <odom_publish_frequency>1</odom_publish_frequency>
      <max_linear_acceleration>1</max_linear_acceleration>
      <min_linear_acceleration>-1</min_linear_acceleration>
      <max_angular_acceleration>2</max_angular_acceleration>
      <min_angular_acceleration>-2</min_angular_acceleration>
      <max_linear_velocity>0.5</max_linear_velocity>
      <min_linear_velocity>-0.5</min_linear_velocity>
      <max_angular_velocity>1</max_angular_velocity>
      <min_angular_velocity>-1</min_angular_velocity>
    </plugin>
  </gazebo>
  <!-- ARUCO SIMULATION
    <link name="aruco_link">
        <visual>
            <geometry>
                <mesh filename="file://$(find kabot_launcher)/description/meshes/aruco.dae" scale="0.03 0.03 0.03"/>
            </geometry>
        </visual>
        <collision>
            <geometry>
                <box size="0.05 0.05 0.01"/>            
            </geometry>
        </collision>
        <xacro:inertial_box mass="0.0001" x="0.0001" y="0.0001" z="0.0001">
            <origin xyz="0 0 0" rpy="0 0 0"/>
        </xacro:inertial_box>
    </link>
    <gazebo reference="aruco_link">
        <material>aruco</material>
    </gazebo>
    <joint name="aruco_link" type="fixed">
        <parent link="chassis_link"/>
        <child link="aruco_link"/>
        <origin xyz="0 0 0.036" rpy="0 ${pi} 0"/>
    </joint> -->
</robot>
