<?xml version="1.0" ?>
<sdf version='1.11'>
  <model name='kabot'>
    <link name='base_link'>
      <inertial>
        <pose>0 0 0 0 0 0</pose>
        <mass>0.10000000000000001</mass>
        <inertia>
          <ixx>0.00013083333333333331</ixx>
          <ixy>0</ixy>
          <ixz>0</ixz>
          <iyy>0.00013083333333333331</iyy>
          <iyz>0</iyz>
          <izz>0.00018000000000000001</izz>
        </inertia>
      </inertial>
      <collision name='base_link_fixed_joint_lump__chassis_link_collision'>
        <pose>0 0 0 0 0 0</pose>
        <geometry>
          <cylinder>
            <length>0.070000000000000007</length>
            <radius>0.059999999999999998</radius>
          </cylinder>
        </geometry>
        <surface>
          <contact>
            <ode/>
          </contact>
          <friction>
            <ode/>
          </friction>
        </surface>
      </collision>
      <visual name='base_link_fixed_joint_lump__chassis_link_visual'>
        <pose>0 0 0 0 0 0</pose>
        <geometry>
          <cylinder>
            <length>0.070000000000000007</length>
            <radius>0.059999999999999998</radius>
          </cylinder>
        </geometry>
        <material>
          <script>
            <name>Gazebo/Orange</name>
            <uri>file://media/materials/scripts/gazebo.material</uri>
          </script>
          <diffuse>1 1 1 1</diffuse>
          <ambient>1 1 1 1</ambient>
        </material>
      </visual>
    </link>
    <joint name='left_wheel_joint' type='revolute'>
      <pose relative_to='base_link'>0 0.065000000000000002 -0.0050000000000000001 -1.5707963267948959 0 0</pose>
      <parent>base_link</parent>
      <child>left_wheel_link</child>
      <axis>
        <xyz>0 0 1</xyz>
        <limit>
          <lower>-inf</lower>
          <upper>inf</upper>
        </limit>
        <dynamics>
          <spring_reference>0</spring_reference>
          <spring_stiffness>0</spring_stiffness>
        </dynamics>
      </axis>
    </joint>
    <link name='left_wheel_link'>
      <pose relative_to='left_wheel_joint'>0 0 0 0 0 0</pose>
      <inertial>
        <pose>0 0 0 0 0 0</pose>
        <mass>0.10000000000000001</mass>
        <inertia>
          <ixx>3.0833333333333342e-05</ixx>
          <ixy>0</ixy>
          <ixz>0</ixz>
          <iyy>3.0833333333333342e-05</iyy>
          <iyz>0</iyz>
          <izz>6.1250000000000012e-05</izz>
        </inertia>
      </inertial>
      <collision name='left_wheel_link_collision'>
        <pose>0 0 0 0 0 0</pose>
        <geometry>
          <cylinder>
            <length>0.0050000000000000001</length>
            <radius>0.035000000000000003</radius>
          </cylinder>
        </geometry>
        <surface>
          <contact>
            <ode/>
          </contact>
          <friction>
            <ode/>
          </friction>
        </surface>
      </collision>
      <visual name='left_wheel_link_visual'>
        <pose>0 0 0 0 0 0</pose>
        <geometry>
          <cylinder>
            <length>0.0050000000000000001</length>
            <radius>0.035000000000000003</radius>
          </cylinder>
        </geometry>
        <material>
          <script>
            <name>Gazebo/Blue</name>
            <uri>file://media/materials/scripts/gazebo.material</uri>
          </script>
          <diffuse>0 0 1 1</diffuse>
          <ambient>0 0 1 1</ambient>
        </material>
      </visual>
    </link>
    <joint name='right_wheel_joint' type='revolute'>
      <pose relative_to='base_link'>0 -0.065000000000000002 -0.0050000000000000001 -1.5707963267948959 0 0</pose>
      <parent>base_link</parent>
      <child>right_wheel_link</child>
      <axis>
        <xyz>0 0 1</xyz>
        <limit>
          <lower>-inf</lower>
          <upper>inf</upper>
        </limit>
        <dynamics>
          <spring_reference>0</spring_reference>
          <spring_stiffness>0</spring_stiffness>
        </dynamics>
      </axis>
    </joint>
    <link name='right_wheel_link'>
      <pose relative_to='right_wheel_joint'>0 0 0 0 0 0</pose>
      <inertial>
        <pose>0 0 0 0 0 0</pose>
        <mass>0.10000000000000001</mass>
        <inertia>
          <ixx>3.0833333333333342e-05</ixx>
          <ixy>0</ixy>
          <ixz>0</ixz>
          <iyy>3.0833333333333342e-05</iyy>
          <iyz>0</iyz>
          <izz>6.1250000000000012e-05</izz>
        </inertia>
      </inertial>
      <collision name='right_wheel_link_collision'>
        <pose>0 0 0 0 0 0</pose>
        <geometry>
          <cylinder>
            <length>0.0050000000000000001</length>
            <radius>0.035000000000000003</radius>
          </cylinder>
        </geometry>
        <surface>
          <contact>
            <ode/>
          </contact>
          <friction>
            <ode/>
          </friction>
        </surface>
      </collision>
      <visual name='right_wheel_link_visual'>
        <pose>0 0 0 0 0 0</pose>
        <geometry>
          <cylinder>
            <length>0.0050000000000000001</length>
            <radius>0.035000000000000003</radius>
          </cylinder>
        </geometry>
        <material>
          <script>
            <name>Gazebo/Blue</name>
            <uri>file://media/materials/scripts/gazebo.material</uri>
          </script>
          <diffuse>0 0 1 1</diffuse>
          <ambient>0 0 1 1</ambient>
        </material>
      </visual>
    </link>
    <plugin name='ignition::gazebo::systems::DiffDrive' filename='ignition-gazebo-diff-drive-system'>
      <left_joint>left_wheel_joint</left_joint>
      <right_joint>right_wheel_joint</right_joint>
      <wheel_separation>0.13</wheel_separation>
      <wheel_radius>0.35</wheel_radius>
      <odom_publish_frequency>1</odom_publish_frequency>
      <max_linear_acceleration>1</max_linear_acceleration>
      <min_linear_acceleration>-1</min_linear_acceleration>
      <max_angular_acceleration>2</max_angular_acceleration>
      <min_angular_acceleration>-2</min_angular_acceleration>
      <max_linear_velocity>0.5</max_linear_velocity>
      <min_linear_velocity>-0.5</min_linear_velocity>
      <max_angular_velocity>1</max_angular_velocity>
      <min_angular_velocity>-1</min_angular_velocity>
    </plugin>
    <frame name='chassis_joint' attached_to='base_link'>
      <pose>0 0 0 0 0 0</pose>
    </frame>
    <frame name='chassis_link' attached_to='chassis_joint'>
      <pose>0 0 0 0 0 0</pose>
    </frame>
    <frame name='footprint_joint' attached_to='base_link'>
      <pose>0 0 -0.035000000000000003 0 0 0</pose>
    </frame>
    <frame name='footprint_link' attached_to='footprint_joint'>
      <pose>0 0 0 0 0 0</pose>
    </frame>
  </model>
</sdf>
